2025-09-29 00:00:00:INFO:Performing scheduled database backup.
2025-09-29 00:00:00:INFO:Backing up SQLite database to /root/.local/share/spoolman/backups/spoolman.db
2025-09-29 00:00:00:INFO:Copied 1 of 24 pages.
2025-09-29 00:00:00:INFO:Copied 2 of 24 pages.
2025-09-29 00:00:00:INFO:Copied 3 of 24 pages.
2025-09-29 00:00:00:INFO:Copied 4 of 24 pages.
2025-09-29 00:00:00:INFO:Copied 5 of 24 pages.
2025-09-29 00:00:00:INFO:Copied 6 of 24 pages.
2025-09-29 00:00:00:INFO:Copied 7 of 24 pages.
2025-09-29 00:00:00:INFO:Copied 8 of 24 pages.
2025-09-29 00:00:00:INFO:Copied 9 of 24 pages.
2025-09-29 00:00:00:INFO:Copied 10 of 24 pages.
2025-09-29 00:00:00:INFO:Copied 11 of 24 pages.
2025-09-29 00:00:00:INFO:Copied 12 of 24 pages.
2025-09-29 00:00:00:INFO:Copied 13 of 24 pages.
2025-09-29 00:00:00:INFO:Copied 14 of 24 pages.
2025-09-29 00:00:00:INFO:Copied 15 of 24 pages.
2025-09-29 00:00:00:INFO:Copied 16 of 24 pages.
2025-09-29 00:00:00:INFO:Copied 17 of 24 pages.
2025-09-29 00:00:00:INFO:Copied 18 of 24 pages.
2025-09-29 00:00:00:INFO:Copied 19 of 24 pages.
2025-09-29 00:00:00:INFO:Copied 20 of 24 pages.
2025-09-29 00:00:00:INFO:Copied 21 of 24 pages.
2025-09-29 00:00:00:INFO:Copied 22 of 24 pages.
2025-09-29 00:00:00:INFO:Copied 23 of 24 pages.
2025-09-29 00:00:00:INFO:Copied 24 of 24 pages.
2025-09-29 00:00:00:INFO:Backup complete.
2025-09-29 00:39:29:INFO:Syncing external DB.
2025-09-29 00:39:29:INFO:HTTP Request: GET https://donkie.github.io/SpoolmanDB/filaments.json "HTTP/1.1 200 OK"
2025-09-29 00:39:29:INFO:HTTP Request: GET https://donkie.github.io/SpoolmanDB/materials.json "HTTP/1.1 200 OK"
2025-09-29 00:39:29:INFO:External DB synced. Filaments: 5913, Materials: 32
2025-09-29 01:39:29:INFO:Syncing external DB.
2025-09-29 01:39:29:INFO:HTTP Request: GET https://donkie.github.io/SpoolmanDB/filaments.json "HTTP/1.1 200 OK"
2025-09-29 01:39:29:INFO:HTTP Request: GET https://donkie.github.io/SpoolmanDB/materials.json "HTTP/1.1 200 OK"
2025-09-29 01:39:29:INFO:External DB synced. Filaments: 5913, Materials: 32
2025-09-29 02:39:29:INFO:Syncing external DB.
2025-09-29 02:39:29:INFO:HTTP Request: GET https://donkie.github.io/SpoolmanDB/filaments.json "HTTP/1.1 200 OK"
2025-09-29 02:39:29:INFO:HTTP Request: GET https://donkie.github.io/SpoolmanDB/materials.json "HTTP/1.1 200 OK"
2025-09-29 02:39:29:INFO:External DB synced. Filaments: 5913, Materials: 32
2025-09-29 03:39:29:INFO:Syncing external DB.
2025-09-29 03:39:29:INFO:HTTP Request: GET https://donkie.github.io/SpoolmanDB/filaments.json "HTTP/1.1 200 OK"
2025-09-29 03:39:29:INFO:HTTP Request: GET https://donkie.github.io/SpoolmanDB/materials.json "HTTP/1.1 200 OK"
2025-09-29 03:39:29:INFO:External DB synced. Filaments: 5913, Materials: 32
2025-09-29 04:39:29:INFO:Syncing external DB.
2025-09-29 04:39:29:INFO:HTTP Request: GET https://donkie.github.io/SpoolmanDB/filaments.json "HTTP/1.1 200 OK"
2025-09-29 04:39:29:INFO:HTTP Request: GET https://donkie.github.io/SpoolmanDB/materials.json "HTTP/1.1 200 OK"
2025-09-29 04:39:29:INFO:External DB synced. Filaments: 5913, Materials: 32
2025-09-29 05:39:29:INFO:Syncing external DB.
2025-09-29 05:39:29:INFO:HTTP Request: GET https://donkie.github.io/SpoolmanDB/filaments.json "HTTP/1.1 200 OK"
2025-09-29 05:39:29:INFO:HTTP Request: GET https://donkie.github.io/SpoolmanDB/materials.json "HTTP/1.1 200 OK"
2025-09-29 05:39:29:INFO:External DB synced. Filaments: 5913, Materials: 32
2025-09-29 06:39:29:INFO:Syncing external DB.
2025-09-29 06:39:29:INFO:HTTP Request: GET https://donkie.github.io/SpoolmanDB/filaments.json "HTTP/1.1 200 OK"
2025-09-29 06:39:29:INFO:HTTP Request: GET https://donkie.github.io/SpoolmanDB/materials.json "HTTP/1.1 200 OK"
2025-09-29 06:39:29:INFO:External DB synced. Filaments: 5913, Materials: 32
2025-09-29 07:39:29:INFO:Syncing external DB.
2025-09-29 07:39:29:INFO:HTTP Request: GET https://donkie.github.io/SpoolmanDB/filaments.json "HTTP/1.1 200 OK"
2025-09-29 07:39:29:INFO:HTTP Request: GET https://donkie.github.io/SpoolmanDB/materials.json "HTTP/1.1 200 OK"
2025-09-29 07:39:29:INFO:External DB synced. Filaments: 5913, Materials: 32
2025-09-29 08:39:29:INFO:Syncing external DB.
2025-09-29 08:39:29:INFO:HTTP Request: GET https://donkie.github.io/SpoolmanDB/filaments.json "HTTP/1.1 200 OK"
2025-09-29 08:39:29:INFO:HTTP Request: GET https://donkie.github.io/SpoolmanDB/materials.json "HTTP/1.1 200 OK"
2025-09-29 08:39:29:INFO:External DB synced. Filaments: 5913, Materials: 32
2025-09-29 09:39:29:INFO:Syncing external DB.
2025-09-29 09:39:29:INFO:HTTP Request: GET https://donkie.github.io/SpoolmanDB/filaments.json "HTTP/1.1 200 OK"
2025-09-29 09:39:29:INFO:HTTP Request: GET https://donkie.github.io/SpoolmanDB/materials.json "HTTP/1.1 200 OK"
2025-09-29 09:39:29:INFO:External DB synced. Filaments: 5913, Materials: 32
2025-09-29 10:14:07:INFO:Client 192.168.1.102 has stopped listening on pool spool
2025-09-29 10:39:29:INFO:Syncing external DB.
2025-09-29 10:39:29:INFO:HTTP Request: GET https://donkie.github.io/SpoolmanDB/filaments.json "HTTP/1.1 200 OK"
2025-09-29 10:39:29:INFO:HTTP Request: GET https://donkie.github.io/SpoolmanDB/materials.json "HTTP/1.1 200 OK"
2025-09-29 10:39:29:INFO:External DB synced. Filaments: 5913, Materials: 32
2025-09-29 11:39:29:INFO:Syncing external DB.
2025-09-29 11:39:29:INFO:HTTP Request: GET https://donkie.github.io/SpoolmanDB/filaments.json "HTTP/1.1 200 OK"
2025-09-29 11:39:29:INFO:HTTP Request: GET https://donkie.github.io/SpoolmanDB/materials.json "HTTP/1.1 200 OK"
2025-09-29 11:39:29:INFO:External DB synced. Filaments: 5913, Materials: 32
2025-09-29 12:39:29:INFO:Syncing external DB.
2025-09-29 12:39:29:INFO:HTTP Request: GET https://donkie.github.io/SpoolmanDB/filaments.json "HTTP/1.1 200 OK"
2025-09-29 12:39:29:INFO:HTTP Request: GET https://donkie.github.io/SpoolmanDB/materials.json "HTTP/1.1 200 OK"
2025-09-29 12:39:29:INFO:External DB synced. Filaments: 5913, Materials: 32
2025-09-29 13:39:29:INFO:Syncing external DB.
2025-09-29 13:39:29:INFO:HTTP Request: GET https://donkie.github.io/SpoolmanDB/filaments.json "HTTP/1.1 200 OK"
2025-09-29 13:39:29:INFO:HTTP Request: GET https://donkie.github.io/SpoolmanDB/materials.json "HTTP/1.1 200 OK"
2025-09-29 13:39:29:INFO:External DB synced. Filaments: 5913, Materials: 32
2025-09-29 14:39:29:INFO:Syncing external DB.
2025-09-29 14:39:29:INFO:HTTP Request: GET https://donkie.github.io/SpoolmanDB/filaments.json "HTTP/1.1 200 OK"
2025-09-29 14:39:29:INFO:HTTP Request: GET https://donkie.github.io/SpoolmanDB/materials.json "HTTP/1.1 200 OK"
2025-09-29 14:39:29:INFO:External DB synced. Filaments: 5913, Materials: 32
2025-09-29 14:59:50:INFO:Client 192.168.1.102 is now listening on pool spool
2025-09-29 15:39:29:INFO:Syncing external DB.
2025-09-29 15:39:29:INFO:HTTP Request: GET https://donkie.github.io/SpoolmanDB/filaments.json "HTTP/1.1 200 OK"
2025-09-29 15:39:29:INFO:HTTP Request: GET https://donkie.github.io/SpoolmanDB/materials.json "HTTP/1.1 200 OK"
2025-09-29 15:39:29:INFO:External DB synced. Filaments: 5913, Materials: 32
2025-09-29 16:14:02:INFO:Client 192.168.1.102 has stopped listening on pool spool
2025-09-29 16:14:15:INFO:Client 192.168.1.102 is now listening on pool spool
2025-09-29 16:39:29:INFO:Syncing external DB.
2025-09-29 16:39:29:INFO:HTTP Request: GET https://donkie.github.io/SpoolmanDB/filaments.json "HTTP/1.1 200 OK"
2025-09-29 16:39:29:INFO:HTTP Request: GET https://donkie.github.io/SpoolmanDB/materials.json "HTTP/1.1 200 OK"
2025-09-29 16:39:29:INFO:External DB synced. Filaments: 5913, Materials: 32
2025-09-29 17:39:29:INFO:Syncing external DB.
2025-09-29 17:39:29:INFO:HTTP Request: GET https://donkie.github.io/SpoolmanDB/filaments.json "HTTP/1.1 200 OK"
2025-09-29 17:39:29:INFO:HTTP Request: GET https://donkie.github.io/SpoolmanDB/materials.json "HTTP/1.1 200 OK"
2025-09-29 17:39:29:INFO:External DB synced. Filaments: 5913, Materials: 32
2025-09-29 18:39:29:INFO:Syncing external DB.
2025-09-29 18:39:34:ERROR:Unhandled exception in `scheduler.asyncio.job.Job(<JobType.CYCLIC: 1>, [datetime.timedelta(seconds=3600)], <function _sync at 0x7975425702c0>, (), {}, 0, True, datetime.datetime(2025, 9, 27, 13, 39, 29, 459468), None, False, None, None)`!
Traceback (most recent call last):
  File "/usr/local/lib/python3.11/dist-packages/httpx/_transports/default.py", line 101, in map_httpcore_exceptions
    yield
  File "/usr/local/lib/python3.11/dist-packages/httpx/_transports/default.py", line 394, in handle_async_request
    resp = await self._pool.handle_async_request(req)
           ^^^^^^^^^^^^^^^^^^^^^^^^^^^^^^^^^^^^^^^^^^
  File "/usr/local/lib/python3.11/dist-packages/httpcore/_async/connection_pool.py", line 256, in handle_async_request
    raise exc from None
  File "/usr/local/lib/python3.11/dist-packages/httpcore/_async/connection_pool.py", line 236, in handle_async_request
    response = await connection.handle_async_request(
               ^^^^^^^^^^^^^^^^^^^^^^^^^^^^^^^^^^^^^^
  File "/usr/local/lib/python3.11/dist-packages/httpcore/_async/connection.py", line 101, in handle_async_request
    raise exc
  File "/usr/local/lib/python3.11/dist-packages/httpcore/_async/connection.py", line 78, in handle_async_request
    stream = await self._connect(request)
             ^^^^^^^^^^^^^^^^^^^^^^^^^^^^
  File "/usr/local/lib/python3.11/dist-packages/httpcore/_async/connection.py", line 124, in _connect
    stream = await self._network_backend.connect_tcp(**kwargs)
             ^^^^^^^^^^^^^^^^^^^^^^^^^^^^^^^^^^^^^^^^^^^^^^^^^
  File "/usr/local/lib/python3.11/dist-packages/httpcore/_backends/auto.py", line 31, in connect_tcp
    return await self._backend.connect_tcp(
           ^^^^^^^^^^^^^^^^^^^^^^^^^^^^^^^^
  File "/usr/local/lib/python3.11/dist-packages/httpcore/_backends/anyio.py", line 113, in connect_tcp
    with map_exceptions(exc_map):
  File "/usr/lib/python3.11/contextlib.py", line 155, in __exit__
    self.gen.throw(typ, value, traceback)
  File "/usr/local/lib/python3.11/dist-packages/httpcore/_exceptions.py", line 14, in map_exceptions
    raise to_exc(exc) from exc
httpcore.ConnectTimeout

The above exception was the direct cause of the following exception:

Traceback (most recent call last):
  File "/usr/local/lib/python3.11/dist-packages/scheduler/asyncio/job.py", line 64, in _exec
    await coroutine
  File "/opt/spoolman/spoolman/externaldb.py", line 174, in _sync
    filaments = _parse_filaments_from_bytes(await _download_file(urljoin(url, "filaments.json")))
                                            ^^^^^^^^^^^^^^^^^^^^^^^^^^^^^^^^^^^^^^^^^^^^^^^^^^^^
  File "/opt/spoolman/spoolman/externaldb.py", line 139, in _download_file
    response = await client.get(url)
               ^^^^^^^^^^^^^^^^^^^^^
  File "/usr/local/lib/python3.11/dist-packages/httpx/_client.py", line 1768, in get
    return await self.request(
           ^^^^^^^^^^^^^^^^^^^
  File "/usr/local/lib/python3.11/dist-packages/httpx/_client.py", line 1540, in request
    return await self.send(request, auth=auth, follow_redirects=follow_redirects)
           ^^^^^^^^^^^^^^^^^^^^^^^^^^^^^^^^^^^^^^^^^^^^^^^^^^^^^^^^^^^^^^^^^^^^^^
  File "/usr/local/lib/python3.11/dist-packages/httpx/_client.py", line 1629, in send
    response = await self._send_handling_auth(
               ^^^^^^^^^^^^^^^^^^^^^^^^^^^^^^^
  File "/usr/local/lib/python3.11/dist-packages/httpx/_client.py", line 1657, in _send_handling_auth
    response = await self._send_handling_redirects(
               ^^^^^^^^^^^^^^^^^^^^^^^^^^^^^^^^^^^^
  File "/usr/local/lib/python3.11/dist-packages/httpx/_client.py", line 1694, in _send_handling_redirects
    response = await self._send_single_request(request)
               ^^^^^^^^^^^^^^^^^^^^^^^^^^^^^^^^^^^^^^^^
  File "/usr/local/lib/python3.11/dist-packages/httpx/_client.py", line 1730, in _send_single_request
    response = await transport.handle_async_request(request)
               ^^^^^^^^^^^^^^^^^^^^^^^^^^^^^^^^^^^^^^^^^^^^^
  File "/usr/local/lib/python3.11/dist-packages/hishel/_async/_transports.py", line 162, in handle_async_request
    revalidation_response = await self._transport.handle_async_request(revalidation_request)
                            ^^^^^^^^^^^^^^^^^^^^^^^^^^^^^^^^^^^^^^^^^^^^^^^^^^^^^^^^^^^^^^^^
  File "/usr/local/lib/python3.11/dist-packages/httpx/_transports/default.py", line 393, in handle_async_request
    with map_httpcore_exceptions():
  File "/usr/lib/python3.11/contextlib.py", line 155, in __exit__
    self.gen.throw(typ, value, traceback)
  File "/usr/local/lib/python3.11/dist-packages/httpx/_transports/default.py", line 118, in map_httpcore_exceptions
    raise mapped_exc(message) from exc
httpx.ConnectTimeout
2025-09-29 19:39:29:INFO:Syncing external DB.
2025-09-29 19:39:34:ERROR:Unhandled exception in `scheduler.asyncio.job.Job(<JobType.CYCLIC: 1>, [datetime.timedelta(seconds=3600)], <function _sync at 0x7975425702c0>, (), {}, 0, True, datetime.datetime(2025, 9, 27, 13, 39, 29, 459468), None, False, None, None)`!
Traceback (most recent call last):
  File "/usr/local/lib/python3.11/dist-packages/httpx/_transports/default.py", line 101, in map_httpcore_exceptions
    yield
  File "/usr/local/lib/python3.11/dist-packages/httpx/_transports/default.py", line 394, in handle_async_request
    resp = await self._pool.handle_async_request(req)
           ^^^^^^^^^^^^^^^^^^^^^^^^^^^^^^^^^^^^^^^^^^
  File "/usr/local/lib/python3.11/dist-packages/httpcore/_async/connection_pool.py", line 256, in handle_async_request
    raise exc from None
  File "/usr/local/lib/python3.11/dist-packages/httpcore/_async/connection_pool.py", line 236, in handle_async_request
    response = await connection.handle_async_request(
               ^^^^^^^^^^^^^^^^^^^^^^^^^^^^^^^^^^^^^^
  File "/usr/local/lib/python3.11/dist-packages/httpcore/_async/connection.py", line 101, in handle_async_request
    raise exc
  File "/usr/local/lib/python3.11/dist-packages/httpcore/_async/connection.py", line 78, in handle_async_request
    stream = await self._connect(request)
             ^^^^^^^^^^^^^^^^^^^^^^^^^^^^
  File "/usr/local/lib/python3.11/dist-packages/httpcore/_async/connection.py", line 124, in _connect
    stream = await self._network_backend.connect_tcp(**kwargs)
             ^^^^^^^^^^^^^^^^^^^^^^^^^^^^^^^^^^^^^^^^^^^^^^^^^
  File "/usr/local/lib/python3.11/dist-packages/httpcore/_backends/auto.py", line 31, in connect_tcp
    return await self._backend.connect_tcp(
           ^^^^^^^^^^^^^^^^^^^^^^^^^^^^^^^^
  File "/usr/local/lib/python3.11/dist-packages/httpcore/_backends/anyio.py", line 113, in connect_tcp
    with map_exceptions(exc_map):
  File "/usr/lib/python3.11/contextlib.py", line 155, in __exit__
    self.gen.throw(typ, value, traceback)
  File "/usr/local/lib/python3.11/dist-packages/httpcore/_exceptions.py", line 14, in map_exceptions
    raise to_exc(exc) from exc
httpcore.ConnectTimeout

The above exception was the direct cause of the following exception:

Traceback (most recent call last):
  File "/usr/local/lib/python3.11/dist-packages/scheduler/asyncio/job.py", line 64, in _exec
    await coroutine
  File "/opt/spoolman/spoolman/externaldb.py", line 174, in _sync
    filaments = _parse_filaments_from_bytes(await _download_file(urljoin(url, "filaments.json")))
                                            ^^^^^^^^^^^^^^^^^^^^^^^^^^^^^^^^^^^^^^^^^^^^^^^^^^^^
  File "/opt/spoolman/spoolman/externaldb.py", line 139, in _download_file
    response = await client.get(url)
               ^^^^^^^^^^^^^^^^^^^^^
  File "/usr/local/lib/python3.11/dist-packages/httpx/_client.py", line 1768, in get
    return await self.request(
           ^^^^^^^^^^^^^^^^^^^
  File "/usr/local/lib/python3.11/dist-packages/httpx/_client.py", line 1540, in request
    return await self.send(request, auth=auth, follow_redirects=follow_redirects)
           ^^^^^^^^^^^^^^^^^^^^^^^^^^^^^^^^^^^^^^^^^^^^^^^^^^^^^^^^^^^^^^^^^^^^^^
  File "/usr/local/lib/python3.11/dist-packages/httpx/_client.py", line 1629, in send
    response = await self._send_handling_auth(
               ^^^^^^^^^^^^^^^^^^^^^^^^^^^^^^^
  File "/usr/local/lib/python3.11/dist-packages/httpx/_client.py", line 1657, in _send_handling_auth
    response = await self._send_handling_redirects(
               ^^^^^^^^^^^^^^^^^^^^^^^^^^^^^^^^^^^^
  File "/usr/local/lib/python3.11/dist-packages/httpx/_client.py", line 1694, in _send_handling_redirects
    response = await self._send_single_request(request)
               ^^^^^^^^^^^^^^^^^^^^^^^^^^^^^^^^^^^^^^^^
  File "/usr/local/lib/python3.11/dist-packages/httpx/_client.py", line 1730, in _send_single_request
    response = await transport.handle_async_request(request)
               ^^^^^^^^^^^^^^^^^^^^^^^^^^^^^^^^^^^^^^^^^^^^^
  File "/usr/local/lib/python3.11/dist-packages/hishel/_async/_transports.py", line 162, in handle_async_request
    revalidation_response = await self._transport.handle_async_request(revalidation_request)
                            ^^^^^^^^^^^^^^^^^^^^^^^^^^^^^^^^^^^^^^^^^^^^^^^^^^^^^^^^^^^^^^^^
  File "/usr/local/lib/python3.11/dist-packages/httpx/_transports/default.py", line 393, in handle_async_request
    with map_httpcore_exceptions():
  File "/usr/lib/python3.11/contextlib.py", line 155, in __exit__
    self.gen.throw(typ, value, traceback)
  File "/usr/local/lib/python3.11/dist-packages/httpx/_transports/default.py", line 118, in map_httpcore_exceptions
    raise mapped_exc(message) from exc
httpx.ConnectTimeout
2025-09-29 19:50:37:INFO:Client 192.168.1.102 has stopped listening on pool spool
2025-09-29 20:39:29:INFO:Syncing external DB.
2025-09-29 20:39:34:ERROR:Unhandled exception in `scheduler.asyncio.job.Job(<JobType.CYCLIC: 1>, [datetime.timedelta(seconds=3600)], <function _sync at 0x7975425702c0>, (), {}, 0, True, datetime.datetime(2025, 9, 27, 13, 39, 29, 459468), None, False, None, None)`!
Traceback (most recent call last):
  File "/usr/local/lib/python3.11/dist-packages/httpx/_transports/default.py", line 101, in map_httpcore_exceptions
    yield
  File "/usr/local/lib/python3.11/dist-packages/httpx/_transports/default.py", line 394, in handle_async_request
    resp = await self._pool.handle_async_request(req)
           ^^^^^^^^^^^^^^^^^^^^^^^^^^^^^^^^^^^^^^^^^^
  File "/usr/local/lib/python3.11/dist-packages/httpcore/_async/connection_pool.py", line 256, in handle_async_request
    raise exc from None
  File "/usr/local/lib/python3.11/dist-packages/httpcore/_async/connection_pool.py", line 236, in handle_async_request
    response = await connection.handle_async_request(
               ^^^^^^^^^^^^^^^^^^^^^^^^^^^^^^^^^^^^^^
  File "/usr/local/lib/python3.11/dist-packages/httpcore/_async/connection.py", line 101, in handle_async_request
    raise exc
  File "/usr/local/lib/python3.11/dist-packages/httpcore/_async/connection.py", line 78, in handle_async_request
    stream = await self._connect(request)
             ^^^^^^^^^^^^^^^^^^^^^^^^^^^^
  File "/usr/local/lib/python3.11/dist-packages/httpcore/_async/connection.py", line 124, in _connect
    stream = await self._network_backend.connect_tcp(**kwargs)
             ^^^^^^^^^^^^^^^^^^^^^^^^^^^^^^^^^^^^^^^^^^^^^^^^^
  File "/usr/local/lib/python3.11/dist-packages/httpcore/_backends/auto.py", line 31, in connect_tcp
    return await self._backend.connect_tcp(
           ^^^^^^^^^^^^^^^^^^^^^^^^^^^^^^^^
  File "/usr/local/lib/python3.11/dist-packages/httpcore/_backends/anyio.py", line 113, in connect_tcp
    with map_exceptions(exc_map):
  File "/usr/lib/python3.11/contextlib.py", line 155, in __exit__
    self.gen.throw(typ, value, traceback)
  File "/usr/local/lib/python3.11/dist-packages/httpcore/_exceptions.py", line 14, in map_exceptions
    raise to_exc(exc) from exc
httpcore.ConnectTimeout

The above exception was the direct cause of the following exception:

Traceback (most recent call last):
  File "/usr/local/lib/python3.11/dist-packages/scheduler/asyncio/job.py", line 64, in _exec
    await coroutine
  File "/opt/spoolman/spoolman/externaldb.py", line 174, in _sync
    filaments = _parse_filaments_from_bytes(await _download_file(urljoin(url, "filaments.json")))
                                            ^^^^^^^^^^^^^^^^^^^^^^^^^^^^^^^^^^^^^^^^^^^^^^^^^^^^
  File "/opt/spoolman/spoolman/externaldb.py", line 139, in _download_file
    response = await client.get(url)
               ^^^^^^^^^^^^^^^^^^^^^
  File "/usr/local/lib/python3.11/dist-packages/httpx/_client.py", line 1768, in get
    return await self.request(
           ^^^^^^^^^^^^^^^^^^^
  File "/usr/local/lib/python3.11/dist-packages/httpx/_client.py", line 1540, in request
    return await self.send(request, auth=auth, follow_redirects=follow_redirects)
           ^^^^^^^^^^^^^^^^^^^^^^^^^^^^^^^^^^^^^^^^^^^^^^^^^^^^^^^^^^^^^^^^^^^^^^
  File "/usr/local/lib/python3.11/dist-packages/httpx/_client.py", line 1629, in send
    response = await self._send_handling_auth(
               ^^^^^^^^^^^^^^^^^^^^^^^^^^^^^^^
  File "/usr/local/lib/python3.11/dist-packages/httpx/_client.py", line 1657, in _send_handling_auth
    response = await self._send_handling_redirects(
               ^^^^^^^^^^^^^^^^^^^^^^^^^^^^^^^^^^^^
  File "/usr/local/lib/python3.11/dist-packages/httpx/_client.py", line 1694, in _send_handling_redirects
    response = await self._send_single_request(request)
               ^^^^^^^^^^^^^^^^^^^^^^^^^^^^^^^^^^^^^^^^
  File "/usr/local/lib/python3.11/dist-packages/httpx/_client.py", line 1730, in _send_single_request
    response = await transport.handle_async_request(request)
               ^^^^^^^^^^^^^^^^^^^^^^^^^^^^^^^^^^^^^^^^^^^^^
  File "/usr/local/lib/python3.11/dist-packages/hishel/_async/_transports.py", line 162, in handle_async_request
    revalidation_response = await self._transport.handle_async_request(revalidation_request)
                            ^^^^^^^^^^^^^^^^^^^^^^^^^^^^^^^^^^^^^^^^^^^^^^^^^^^^^^^^^^^^^^^^
  File "/usr/local/lib/python3.11/dist-packages/httpx/_transports/default.py", line 393, in handle_async_request
    with map_httpcore_exceptions():
  File "/usr/lib/python3.11/contextlib.py", line 155, in __exit__
    self.gen.throw(typ, value, traceback)
  File "/usr/local/lib/python3.11/dist-packages/httpx/_transports/default.py", line 118, in map_httpcore_exceptions
    raise mapped_exc(message) from exc
httpx.ConnectTimeout
2025-09-29 21:39:29:INFO:Syncing external DB.
2025-09-29 21:39:34:ERROR:Unhandled exception in `scheduler.asyncio.job.Job(<JobType.CYCLIC: 1>, [datetime.timedelta(seconds=3600)], <function _sync at 0x7975425702c0>, (), {}, 0, True, datetime.datetime(2025, 9, 27, 13, 39, 29, 459468), None, False, None, None)`!
Traceback (most recent call last):
  File "/usr/local/lib/python3.11/dist-packages/httpx/_transports/default.py", line 101, in map_httpcore_exceptions
    yield
  File "/usr/local/lib/python3.11/dist-packages/httpx/_transports/default.py", line 394, in handle_async_request
    resp = await self._pool.handle_async_request(req)
           ^^^^^^^^^^^^^^^^^^^^^^^^^^^^^^^^^^^^^^^^^^
  File "/usr/local/lib/python3.11/dist-packages/httpcore/_async/connection_pool.py", line 256, in handle_async_request
    raise exc from None
  File "/usr/local/lib/python3.11/dist-packages/httpcore/_async/connection_pool.py", line 236, in handle_async_request
    response = await connection.handle_async_request(
               ^^^^^^^^^^^^^^^^^^^^^^^^^^^^^^^^^^^^^^
  File "/usr/local/lib/python3.11/dist-packages/httpcore/_async/connection.py", line 101, in handle_async_request
    raise exc
  File "/usr/local/lib/python3.11/dist-packages/httpcore/_async/connection.py", line 78, in handle_async_request
    stream = await self._connect(request)
             ^^^^^^^^^^^^^^^^^^^^^^^^^^^^
  File "/usr/local/lib/python3.11/dist-packages/httpcore/_async/connection.py", line 124, in _connect
    stream = await self._network_backend.connect_tcp(**kwargs)
             ^^^^^^^^^^^^^^^^^^^^^^^^^^^^^^^^^^^^^^^^^^^^^^^^^
  File "/usr/local/lib/python3.11/dist-packages/httpcore/_backends/auto.py", line 31, in connect_tcp
    return await self._backend.connect_tcp(
           ^^^^^^^^^^^^^^^^^^^^^^^^^^^^^^^^
  File "/usr/local/lib/python3.11/dist-packages/httpcore/_backends/anyio.py", line 113, in connect_tcp
    with map_exceptions(exc_map):
  File "/usr/lib/python3.11/contextlib.py", line 155, in __exit__
    self.gen.throw(typ, value, traceback)
  File "/usr/local/lib/python3.11/dist-packages/httpcore/_exceptions.py", line 14, in map_exceptions
    raise to_exc(exc) from exc
httpcore.ConnectTimeout

The above exception was the direct cause of the following exception:

Traceback (most recent call last):
  File "/usr/local/lib/python3.11/dist-packages/scheduler/asyncio/job.py", line 64, in _exec
    await coroutine
  File "/opt/spoolman/spoolman/externaldb.py", line 174, in _sync
    filaments = _parse_filaments_from_bytes(await _download_file(urljoin(url, "filaments.json")))
                                            ^^^^^^^^^^^^^^^^^^^^^^^^^^^^^^^^^^^^^^^^^^^^^^^^^^^^
  File "/opt/spoolman/spoolman/externaldb.py", line 139, in _download_file
    response = await client.get(url)
               ^^^^^^^^^^^^^^^^^^^^^
  File "/usr/local/lib/python3.11/dist-packages/httpx/_client.py", line 1768, in get
    return await self.request(
           ^^^^^^^^^^^^^^^^^^^
  File "/usr/local/lib/python3.11/dist-packages/httpx/_client.py", line 1540, in request
    return await self.send(request, auth=auth, follow_redirects=follow_redirects)
           ^^^^^^^^^^^^^^^^^^^^^^^^^^^^^^^^^^^^^^^^^^^^^^^^^^^^^^^^^^^^^^^^^^^^^^
  File "/usr/local/lib/python3.11/dist-packages/httpx/_client.py", line 1629, in send
    response = await self._send_handling_auth(
               ^^^^^^^^^^^^^^^^^^^^^^^^^^^^^^^
  File "/usr/local/lib/python3.11/dist-packages/httpx/_client.py", line 1657, in _send_handling_auth
    response = await self._send_handling_redirects(
               ^^^^^^^^^^^^^^^^^^^^^^^^^^^^^^^^^^^^
  File "/usr/local/lib/python3.11/dist-packages/httpx/_client.py", line 1694, in _send_handling_redirects
    response = await self._send_single_request(request)
               ^^^^^^^^^^^^^^^^^^^^^^^^^^^^^^^^^^^^^^^^
  File "/usr/local/lib/python3.11/dist-packages/httpx/_client.py", line 1730, in _send_single_request
    response = await transport.handle_async_request(request)
               ^^^^^^^^^^^^^^^^^^^^^^^^^^^^^^^^^^^^^^^^^^^^^
  File "/usr/local/lib/python3.11/dist-packages/hishel/_async/_transports.py", line 162, in handle_async_request
    revalidation_response = await self._transport.handle_async_request(revalidation_request)
                            ^^^^^^^^^^^^^^^^^^^^^^^^^^^^^^^^^^^^^^^^^^^^^^^^^^^^^^^^^^^^^^^^
  File "/usr/local/lib/python3.11/dist-packages/httpx/_transports/default.py", line 393, in handle_async_request
    with map_httpcore_exceptions():
  File "/usr/lib/python3.11/contextlib.py", line 155, in __exit__
    self.gen.throw(typ, value, traceback)
  File "/usr/local/lib/python3.11/dist-packages/httpx/_transports/default.py", line 118, in map_httpcore_exceptions
    raise mapped_exc(message) from exc
httpx.ConnectTimeout
2025-09-29 21:46:14:INFO:Client 192.168.1.134 is now listening on pool spool
2025-09-29 21:47:24:INFO:Client 192.168.1.134 has stopped listening on pool spool
2025-09-29 21:48:01:INFO:Client 192.168.1.102 is now listening on pool spool
2025-09-29 22:33:34:INFO:Client 192.168.1.102 has stopped listening on pool spool
2025-09-29 22:33:50:INFO:Client 192.168.1.102 is now listening on pool spool
2025-09-29 22:39:29:INFO:Syncing external DB.
2025-09-29 22:39:34:ERROR:Unhandled exception in `scheduler.asyncio.job.Job(<JobType.CYCLIC: 1>, [datetime.timedelta(seconds=3600)], <function _sync at 0x7975425702c0>, (), {}, 0, True, datetime.datetime(2025, 9, 27, 13, 39, 29, 459468), None, False, None, None)`!
Traceback (most recent call last):
  File "/usr/local/lib/python3.11/dist-packages/httpx/_transports/default.py", line 101, in map_httpcore_exceptions
    yield
  File "/usr/local/lib/python3.11/dist-packages/httpx/_transports/default.py", line 394, in handle_async_request
    resp = await self._pool.handle_async_request(req)
           ^^^^^^^^^^^^^^^^^^^^^^^^^^^^^^^^^^^^^^^^^^
  File "/usr/local/lib/python3.11/dist-packages/httpcore/_async/connection_pool.py", line 256, in handle_async_request
    raise exc from None
  File "/usr/local/lib/python3.11/dist-packages/httpcore/_async/connection_pool.py", line 236, in handle_async_request
    response = await connection.handle_async_request(
               ^^^^^^^^^^^^^^^^^^^^^^^^^^^^^^^^^^^^^^
  File "/usr/local/lib/python3.11/dist-packages/httpcore/_async/connection.py", line 101, in handle_async_request
    raise exc
  File "/usr/local/lib/python3.11/dist-packages/httpcore/_async/connection.py", line 78, in handle_async_request
    stream = await self._connect(request)
             ^^^^^^^^^^^^^^^^^^^^^^^^^^^^
  File "/usr/local/lib/python3.11/dist-packages/httpcore/_async/connection.py", line 124, in _connect
    stream = await self._network_backend.connect_tcp(**kwargs)
             ^^^^^^^^^^^^^^^^^^^^^^^^^^^^^^^^^^^^^^^^^^^^^^^^^
  File "/usr/local/lib/python3.11/dist-packages/httpcore/_backends/auto.py", line 31, in connect_tcp
    return await self._backend.connect_tcp(
           ^^^^^^^^^^^^^^^^^^^^^^^^^^^^^^^^
  File "/usr/local/lib/python3.11/dist-packages/httpcore/_backends/anyio.py", line 113, in connect_tcp
    with map_exceptions(exc_map):
  File "/usr/lib/python3.11/contextlib.py", line 155, in __exit__
    self.gen.throw(typ, value, traceback)
  File "/usr/local/lib/python3.11/dist-packages/httpcore/_exceptions.py", line 14, in map_exceptions
    raise to_exc(exc) from exc
httpcore.ConnectTimeout

The above exception was the direct cause of the following exception:

Traceback (most recent call last):
  File "/usr/local/lib/python3.11/dist-packages/scheduler/asyncio/job.py", line 64, in _exec
    await coroutine
  File "/opt/spoolman/spoolman/externaldb.py", line 174, in _sync
    filaments = _parse_filaments_from_bytes(await _download_file(urljoin(url, "filaments.json")))
                                            ^^^^^^^^^^^^^^^^^^^^^^^^^^^^^^^^^^^^^^^^^^^^^^^^^^^^
  File "/opt/spoolman/spoolman/externaldb.py", line 139, in _download_file
    response = await client.get(url)
               ^^^^^^^^^^^^^^^^^^^^^
  File "/usr/local/lib/python3.11/dist-packages/httpx/_client.py", line 1768, in get
    return await self.request(
           ^^^^^^^^^^^^^^^^^^^
  File "/usr/local/lib/python3.11/dist-packages/httpx/_client.py", line 1540, in request
    return await self.send(request, auth=auth, follow_redirects=follow_redirects)
           ^^^^^^^^^^^^^^^^^^^^^^^^^^^^^^^^^^^^^^^^^^^^^^^^^^^^^^^^^^^^^^^^^^^^^^
  File "/usr/local/lib/python3.11/dist-packages/httpx/_client.py", line 1629, in send
    response = await self._send_handling_auth(
               ^^^^^^^^^^^^^^^^^^^^^^^^^^^^^^^
  File "/usr/local/lib/python3.11/dist-packages/httpx/_client.py", line 1657, in _send_handling_auth
    response = await self._send_handling_redirects(
               ^^^^^^^^^^^^^^^^^^^^^^^^^^^^^^^^^^^^
  File "/usr/local/lib/python3.11/dist-packages/httpx/_client.py", line 1694, in _send_handling_redirects
    response = await self._send_single_request(request)
               ^^^^^^^^^^^^^^^^^^^^^^^^^^^^^^^^^^^^^^^^
  File "/usr/local/lib/python3.11/dist-packages/httpx/_client.py", line 1730, in _send_single_request
    response = await transport.handle_async_request(request)
               ^^^^^^^^^^^^^^^^^^^^^^^^^^^^^^^^^^^^^^^^^^^^^
  File "/usr/local/lib/python3.11/dist-packages/hishel/_async/_transports.py", line 162, in handle_async_request
    revalidation_response = await self._transport.handle_async_request(revalidation_request)
                            ^^^^^^^^^^^^^^^^^^^^^^^^^^^^^^^^^^^^^^^^^^^^^^^^^^^^^^^^^^^^^^^^
  File "/usr/local/lib/python3.11/dist-packages/httpx/_transports/default.py", line 393, in handle_async_request
    with map_httpcore_exceptions():
  File "/usr/lib/python3.11/contextlib.py", line 155, in __exit__
    self.gen.throw(typ, value, traceback)
  File "/usr/local/lib/python3.11/dist-packages/httpx/_transports/default.py", line 118, in map_httpcore_exceptions
    raise mapped_exc(message) from exc
httpx.ConnectTimeout
2025-09-29 23:39:29:INFO:Syncing external DB.
2025-09-29 23:39:29:INFO:HTTP Request: GET https://donkie.github.io/SpoolmanDB/filaments.json "HTTP/1.1 200 OK"
2025-09-29 23:39:29:INFO:HTTP Request: GET https://donkie.github.io/SpoolmanDB/materials.json "HTTP/1.1 200 OK"
2025-09-29 23:39:29:INFO:External DB synced. Filaments: 5913, Materials: 32
2025-09-29 23:59:59:INFO:Performing scheduled database backup.
